You're accessing the development server over HTTPS, but it only supports HTTP.
You're accessing the development server over HTTPS, but it only supports HTTP.
You're accessing the development server over HTTPS, but it only supports HTTP.
You're accessing the development server over HTTPS, but it only supports HTTP.
Internal Server Error: /admin/website/aboutsection/1/change/
Traceback (most recent call last):
  File "/home/pryog/NAVODAYAN/venv/lib/python3.13/site-packages/django/core/handlers/exception.py", line 55, in inner
    response = get_response(request)
  File "/home/pryog/NAVODAYAN/venv/lib/python3.13/site-packages/django/core/handlers/base.py", line 197, in _get_response
    response = wrapped_callback(request, *callback_args, **callback_kwargs)
  File "/home/pryog/NAVODAYAN/venv/lib/python3.13/site-packages/django/contrib/admin/options.py", line 719, in wrapper
    return self.admin_site.admin_view(view)(*args, **kwargs)
           ~~~~~~~~~~~~~~~~~~~~~~~~~~~~~~~~^^^^^^^^^^^^^^^^^
  File "/home/pryog/NAVODAYAN/venv/lib/python3.13/site-packages/django/utils/decorators.py", line 192, in _view_wrapper
    result = _process_exception(request, e)
  File "/home/pryog/NAVODAYAN/venv/lib/python3.13/site-packages/django/utils/decorators.py", line 190, in _view_wrapper
    response = view_func(request, *args, **kwargs)
  File "/home/pryog/NAVODAYAN/venv/lib/python3.13/site-packages/django/views/decorators/cache.py", line 80, in _view_wrapper
    response = view_func(request, *args, **kwargs)
  File "/home/pryog/NAVODAYAN/venv/lib/python3.13/site-packages/django/contrib/admin/sites.py", line 246, in inner
    return view(request, *args, **kwargs)
  File "/home/pryog/NAVODAYAN/venv/lib/python3.13/site-packages/django/contrib/admin/options.py", line 1987, in change_view
    return self.changeform_view(request, object_id, form_url, extra_context)
           ~~~~~~~~~~~~~~~~~~~~^^^^^^^^^^^^^^^^^^^^^^^^^^^^^^^^^^^^^^^^^^^^^
  File "/home/pryog/NAVODAYAN/venv/lib/python3.13/site-packages/django/utils/decorators.py", line 48, in _wrapper
    return bound_method(*args, **kwargs)
  File "/home/pryog/NAVODAYAN/venv/lib/python3.13/site-packages/django/utils/decorators.py", line 192, in _view_wrapper
    result = _process_exception(request, e)
  File "/home/pryog/NAVODAYAN/venv/lib/python3.13/site-packages/django/utils/decorators.py", line 190, in _view_wrapper
    response = view_func(request, *args, **kwargs)
  File "/home/pryog/NAVODAYAN/venv/lib/python3.13/site-packages/django/contrib/admin/options.py", line 1843, in changeform_view
    return self._changeform_view(request, object_id, form_url, extra_context)
           ~~~~~~~~~~~~~~~~~~~~~^^^^^^^^^^^^^^^^^^^^^^^^^^^^^^^^^^^^^^^^^^^^^
  File "/home/pryog/NAVODAYAN/venv/lib/python3.13/site-packages/django/contrib/admin/options.py", line 1894, in _changeform_view
    self.save_model(request, new_object, form, not add)
    ~~~~~~~~~~~~~~~^^^^^^^^^^^^^^^^^^^^^^^^^^^^^^^^^^^^
  File "/home/pryog/NAVODAYAN/venv/lib/python3.13/site-packages/django/contrib/admin/options.py", line 1314, in save_model
    obj.save()
    ~~~~~~~~^^
  File "/home/pryog/NAVODAYAN/venv/lib/python3.13/site-packages/django/db/models/base.py", line 902, in save
    self.save_base(
    ~~~~~~~~~~~~~~^
        using=using,
        ^^^^^^^^^^^^
    ...<2 lines>...
        update_fields=update_fields,
        ^^^^^^^^^^^^^^^^^^^^^^^^^^^^
    )
    ^
  File "/home/pryog/NAVODAYAN/venv/lib/python3.13/site-packages/django/db/models/base.py", line 1008, in save_base
    updated = self._save_table(
        raw,
    ...<4 lines>...
        update_fields,
    )
  File "/home/pryog/NAVODAYAN/venv/lib/python3.13/site-packages/django/db/models/base.py", line 1132, in _save_table
    (getattr(self, f.attname) if raw else f.pre_save(self, False)),
                                          ~~~~~~~~~~^^^^^^^^^^^^^
  File "/home/pryog/NAVODAYAN/venv/lib/python3.13/site-packages/django/db/models/fields/files.py", line 338, in pre_save
    file.save(file.name, file.file, save=False)
    ~~~~~~~~~^^^^^^^^^^^^^^^^^^^^^^^^^^^^^^^^^^
  File "/home/pryog/NAVODAYAN/venv/lib/python3.13/site-packages/django/db/models/fields/files.py", line 99, in save
    self.name = self.storage.save(name, content, max_length=self.field.max_length)
                ~~~~~~~~~~~~~~~~~^^^^^^^^^^^^^^^^^^^^^^^^^^^^^^^^^^^^^^^^^^^^^^^^^
  File "/home/pryog/NAVODAYAN/venv/lib/python3.13/site-packages/django/core/files/storage/base.py", line 49, in save
    name = self._save(name, content)
  File "/home/pryog/NAVODAYAN/venv/lib/python3.13/site-packages/django/core/files/storage/filesystem.py", line 137, in _save
    fd = os.open(full_path, open_flags, 0o666)
PermissionError: [Errno 13] Permission denied: '/home/pryog/NAVODAYAN/haminavodayaho/media/about/s1.1.png'
"POST /admin/website/aboutsection/1/change/ HTTP/1.1" 500 145
Internal Server Error: /admin/website/aboutsection/1/change/
Traceback (most recent call last):
  File "/home/pryog/NAVODAYAN/venv/lib/python3.13/site-packages/django/core/handlers/exception.py", line 55, in inner
    response = get_response(request)
  File "/home/pryog/NAVODAYAN/venv/lib/python3.13/site-packages/django/core/handlers/base.py", line 197, in _get_response
    response = wrapped_callback(request, *callback_args, **callback_kwargs)
  File "/home/pryog/NAVODAYAN/venv/lib/python3.13/site-packages/django/contrib/admin/options.py", line 719, in wrapper
    return self.admin_site.admin_view(view)(*args, **kwargs)
           ~~~~~~~~~~~~~~~~~~~~~~~~~~~~~~~~^^^^^^^^^^^^^^^^^
  File "/home/pryog/NAVODAYAN/venv/lib/python3.13/site-packages/django/utils/decorators.py", line 192, in _view_wrapper
    result = _process_exception(request, e)
  File "/home/pryog/NAVODAYAN/venv/lib/python3.13/site-packages/django/utils/decorators.py", line 190, in _view_wrapper
    response = view_func(request, *args, **kwargs)
  File "/home/pryog/NAVODAYAN/venv/lib/python3.13/site-packages/django/views/decorators/cache.py", line 80, in _view_wrapper
    response = view_func(request, *args, **kwargs)
  File "/home/pryog/NAVODAYAN/venv/lib/python3.13/site-packages/django/contrib/admin/sites.py", line 246, in inner
    return view(request, *args, **kwargs)
  File "/home/pryog/NAVODAYAN/venv/lib/python3.13/site-packages/django/contrib/admin/options.py", line 1987, in change_view
    return self.changeform_view(request, object_id, form_url, extra_context)
           ~~~~~~~~~~~~~~~~~~~~^^^^^^^^^^^^^^^^^^^^^^^^^^^^^^^^^^^^^^^^^^^^^
  File "/home/pryog/NAVODAYAN/venv/lib/python3.13/site-packages/django/utils/decorators.py", line 48, in _wrapper
    return bound_method(*args, **kwargs)
  File "/home/pryog/NAVODAYAN/venv/lib/python3.13/site-packages/django/utils/decorators.py", line 192, in _view_wrapper
    result = _process_exception(request, e)
  File "/home/pryog/NAVODAYAN/venv/lib/python3.13/site-packages/django/utils/decorators.py", line 190, in _view_wrapper
    response = view_func(request, *args, **kwargs)
  File "/home/pryog/NAVODAYAN/venv/lib/python3.13/site-packages/django/contrib/admin/options.py", line 1843, in changeform_view
    return self._changeform_view(request, object_id, form_url, extra_context)
           ~~~~~~~~~~~~~~~~~~~~~^^^^^^^^^^^^^^^^^^^^^^^^^^^^^^^^^^^^^^^^^^^^^
  File "/home/pryog/NAVODAYAN/venv/lib/python3.13/site-packages/django/contrib/admin/options.py", line 1894, in _changeform_view
    self.save_model(request, new_object, form, not add)
    ~~~~~~~~~~~~~~~^^^^^^^^^^^^^^^^^^^^^^^^^^^^^^^^^^^^
  File "/home/pryog/NAVODAYAN/venv/lib/python3.13/site-packages/django/contrib/admin/options.py", line 1314, in save_model
    obj.save()
    ~~~~~~~~^^
  File "/home/pryog/NAVODAYAN/venv/lib/python3.13/site-packages/django/db/models/base.py", line 902, in save
    self.save_base(
    ~~~~~~~~~~~~~~^
        using=using,
        ^^^^^^^^^^^^
    ...<2 lines>...
        update_fields=update_fields,
        ^^^^^^^^^^^^^^^^^^^^^^^^^^^^
    )
    ^
  File "/home/pryog/NAVODAYAN/venv/lib/python3.13/site-packages/django/db/models/base.py", line 1008, in save_base
    updated = self._save_table(
        raw,
    ...<4 lines>...
        update_fields,
    )
  File "/home/pryog/NAVODAYAN/venv/lib/python3.13/site-packages/django/db/models/base.py", line 1132, in _save_table
    (getattr(self, f.attname) if raw else f.pre_save(self, False)),
                                          ~~~~~~~~~~^^^^^^^^^^^^^
  File "/home/pryog/NAVODAYAN/venv/lib/python3.13/site-packages/django/db/models/fields/files.py", line 338, in pre_save
    file.save(file.name, file.file, save=False)
    ~~~~~~~~~^^^^^^^^^^^^^^^^^^^^^^^^^^^^^^^^^^
  File "/home/pryog/NAVODAYAN/venv/lib/python3.13/site-packages/django/db/models/fields/files.py", line 99, in save
    self.name = self.storage.save(name, content, max_length=self.field.max_length)
                ~~~~~~~~~~~~~~~~~^^^^^^^^^^^^^^^^^^^^^^^^^^^^^^^^^^^^^^^^^^^^^^^^^
  File "/home/pryog/NAVODAYAN/venv/lib/python3.13/site-packages/django/core/files/storage/base.py", line 49, in save
    name = self._save(name, content)
  File "/home/pryog/NAVODAYAN/venv/lib/python3.13/site-packages/django/core/files/storage/filesystem.py", line 137, in _save
    fd = os.open(full_path, open_flags, 0o666)
PermissionError: [Errno 13] Permission denied: '/home/pryog/NAVODAYAN/haminavodayaho/media/about/s1.1.png'
"POST /admin/website/aboutsection/1/change/ HTTP/1.1" 500 145
Internal Server Error: /admin/website/aboutsection/1/change/
Traceback (most recent call last):
  File "/home/pryog/NAVODAYAN/venv/lib/python3.13/site-packages/django/core/handlers/exception.py", line 55, in inner
    response = get_response(request)
  File "/home/pryog/NAVODAYAN/venv/lib/python3.13/site-packages/django/core/handlers/base.py", line 197, in _get_response
    response = wrapped_callback(request, *callback_args, **callback_kwargs)
  File "/home/pryog/NAVODAYAN/venv/lib/python3.13/site-packages/django/contrib/admin/options.py", line 719, in wrapper
    return self.admin_site.admin_view(view)(*args, **kwargs)
           ~~~~~~~~~~~~~~~~~~~~~~~~~~~~~~~~^^^^^^^^^^^^^^^^^
  File "/home/pryog/NAVODAYAN/venv/lib/python3.13/site-packages/django/utils/decorators.py", line 192, in _view_wrapper
    result = _process_exception(request, e)
  File "/home/pryog/NAVODAYAN/venv/lib/python3.13/site-packages/django/utils/decorators.py", line 190, in _view_wrapper
    response = view_func(request, *args, **kwargs)
  File "/home/pryog/NAVODAYAN/venv/lib/python3.13/site-packages/django/views/decorators/cache.py", line 80, in _view_wrapper
    response = view_func(request, *args, **kwargs)
  File "/home/pryog/NAVODAYAN/venv/lib/python3.13/site-packages/django/contrib/admin/sites.py", line 246, in inner
    return view(request, *args, **kwargs)
  File "/home/pryog/NAVODAYAN/venv/lib/python3.13/site-packages/django/contrib/admin/options.py", line 1987, in change_view
    return self.changeform_view(request, object_id, form_url, extra_context)
           ~~~~~~~~~~~~~~~~~~~~^^^^^^^^^^^^^^^^^^^^^^^^^^^^^^^^^^^^^^^^^^^^^
  File "/home/pryog/NAVODAYAN/venv/lib/python3.13/site-packages/django/utils/decorators.py", line 48, in _wrapper
    return bound_method(*args, **kwargs)
  File "/home/pryog/NAVODAYAN/venv/lib/python3.13/site-packages/django/utils/decorators.py", line 192, in _view_wrapper
    result = _process_exception(request, e)
  File "/home/pryog/NAVODAYAN/venv/lib/python3.13/site-packages/django/utils/decorators.py", line 190, in _view_wrapper
    response = view_func(request, *args, **kwargs)
  File "/home/pryog/NAVODAYAN/venv/lib/python3.13/site-packages/django/contrib/admin/options.py", line 1843, in changeform_view
    return self._changeform_view(request, object_id, form_url, extra_context)
           ~~~~~~~~~~~~~~~~~~~~~^^^^^^^^^^^^^^^^^^^^^^^^^^^^^^^^^^^^^^^^^^^^^
  File "/home/pryog/NAVODAYAN/venv/lib/python3.13/site-packages/django/contrib/admin/options.py", line 1894, in _changeform_view
    self.save_model(request, new_object, form, not add)
    ~~~~~~~~~~~~~~~^^^^^^^^^^^^^^^^^^^^^^^^^^^^^^^^^^^^
  File "/home/pryog/NAVODAYAN/venv/lib/python3.13/site-packages/django/contrib/admin/options.py", line 1314, in save_model
    obj.save()
    ~~~~~~~~^^
  File "/home/pryog/NAVODAYAN/venv/lib/python3.13/site-packages/django/db/models/base.py", line 902, in save
    self.save_base(
    ~~~~~~~~~~~~~~^
        using=using,
        ^^^^^^^^^^^^
    ...<2 lines>...
        update_fields=update_fields,
        ^^^^^^^^^^^^^^^^^^^^^^^^^^^^
    )
    ^
  File "/home/pryog/NAVODAYAN/venv/lib/python3.13/site-packages/django/db/models/base.py", line 1008, in save_base
    updated = self._save_table(
        raw,
    ...<4 lines>...
        update_fields,
    )
  File "/home/pryog/NAVODAYAN/venv/lib/python3.13/site-packages/django/db/models/base.py", line 1132, in _save_table
    (getattr(self, f.attname) if raw else f.pre_save(self, False)),
                                          ~~~~~~~~~~^^^^^^^^^^^^^
  File "/home/pryog/NAVODAYAN/venv/lib/python3.13/site-packages/django/db/models/fields/files.py", line 338, in pre_save
    file.save(file.name, file.file, save=False)
    ~~~~~~~~~^^^^^^^^^^^^^^^^^^^^^^^^^^^^^^^^^^
  File "/home/pryog/NAVODAYAN/venv/lib/python3.13/site-packages/django/db/models/fields/files.py", line 99, in save
    self.name = self.storage.save(name, content, max_length=self.field.max_length)
                ~~~~~~~~~~~~~~~~~^^^^^^^^^^^^^^^^^^^^^^^^^^^^^^^^^^^^^^^^^^^^^^^^^
  File "/home/pryog/NAVODAYAN/venv/lib/python3.13/site-packages/django/core/files/storage/base.py", line 49, in save
    name = self._save(name, content)
  File "/home/pryog/NAVODAYAN/venv/lib/python3.13/site-packages/django/core/files/storage/filesystem.py", line 137, in _save
    fd = os.open(full_path, open_flags, 0o666)
PermissionError: [Errno 13] Permission denied: '/home/pryog/NAVODAYAN/haminavodayaho/media/about/s1.png'
"POST /admin/website/aboutsection/1/change/ HTTP/1.1" 500 145
Internal Server Error: /admin/website/aboutsection/1/change/
Traceback (most recent call last):
  File "/home/pryog/NAVODAYAN/venv/lib/python3.13/site-packages/asgiref/sync.py", line 518, in thread_handler
    raise exc_info[1]
  File "/home/pryog/NAVODAYAN/venv/lib/python3.13/site-packages/django/core/handlers/exception.py", line 42, in inner
    response = await get_response(request)
               ^^^^^^^^^^^^^^^^^^^^^^^^^^^
  File "/home/pryog/NAVODAYAN/venv/lib/python3.13/site-packages/asgiref/sync.py", line 518, in thread_handler
    raise exc_info[1]
  File "/home/pryog/NAVODAYAN/venv/lib/python3.13/site-packages/django/core/handlers/base.py", line 253, in _get_response_async
    response = await wrapped_callback(
               ^^^^^^^^^^^^^^^^^^^^^^^
        request, *callback_args, **callback_kwargs
        ^^^^^^^^^^^^^^^^^^^^^^^^^^^^^^^^^^^^^^^^^^
    )
    ^
  File "/home/pryog/NAVODAYAN/venv/lib/python3.13/site-packages/asgiref/sync.py", line 468, in __call__
    ret = await asyncio.shield(exec_coro)
          ^^^^^^^^^^^^^^^^^^^^^^^^^^^^^^^
  File "/home/pryog/NAVODAYAN/venv/lib/python3.13/site-packages/asgiref/current_thread_executor.py", line 40, in run
    result = self.fn(*self.args, **self.kwargs)
  File "/home/pryog/NAVODAYAN/venv/lib/python3.13/site-packages/asgiref/sync.py", line 522, in thread_handler
    return func(*args, **kwargs)
  File "/home/pryog/NAVODAYAN/venv/lib/python3.13/site-packages/django/contrib/admin/options.py", line 719, in wrapper
    return self.admin_site.admin_view(view)(*args, **kwargs)
           ~~~~~~~~~~~~~~~~~~~~~~~~~~~~~~~~^^^^^^^^^^^^^^^^^
  File "/home/pryog/NAVODAYAN/venv/lib/python3.13/site-packages/django/utils/decorators.py", line 192, in _view_wrapper
    result = _process_exception(request, e)
  File "/home/pryog/NAVODAYAN/venv/lib/python3.13/site-packages/django/utils/decorators.py", line 190, in _view_wrapper
    response = view_func(request, *args, **kwargs)
  File "/home/pryog/NAVODAYAN/venv/lib/python3.13/site-packages/django/views/decorators/cache.py", line 80, in _view_wrapper
    response = view_func(request, *args, **kwargs)
  File "/home/pryog/NAVODAYAN/venv/lib/python3.13/site-packages/django/contrib/admin/sites.py", line 246, in inner
    return view(request, *args, **kwargs)
  File "/home/pryog/NAVODAYAN/venv/lib/python3.13/site-packages/django/contrib/admin/options.py", line 1987, in change_view
    return self.changeform_view(request, object_id, form_url, extra_context)
           ~~~~~~~~~~~~~~~~~~~~^^^^^^^^^^^^^^^^^^^^^^^^^^^^^^^^^^^^^^^^^^^^^
  File "/home/pryog/NAVODAYAN/venv/lib/python3.13/site-packages/django/utils/decorators.py", line 48, in _wrapper
    return bound_method(*args, **kwargs)
  File "/home/pryog/NAVODAYAN/venv/lib/python3.13/site-packages/django/utils/decorators.py", line 192, in _view_wrapper
    result = _process_exception(request, e)
  File "/home/pryog/NAVODAYAN/venv/lib/python3.13/site-packages/django/utils/decorators.py", line 190, in _view_wrapper
    response = view_func(request, *args, **kwargs)
  File "/home/pryog/NAVODAYAN/venv/lib/python3.13/site-packages/django/contrib/admin/options.py", line 1843, in changeform_view
    return self._changeform_view(request, object_id, form_url, extra_context)
           ~~~~~~~~~~~~~~~~~~~~~^^^^^^^^^^^^^^^^^^^^^^^^^^^^^^^^^^^^^^^^^^^^^
  File "/home/pryog/NAVODAYAN/venv/lib/python3.13/site-packages/django/contrib/admin/options.py", line 1894, in _changeform_view
    self.save_model(request, new_object, form, not add)
    ~~~~~~~~~~~~~~~^^^^^^^^^^^^^^^^^^^^^^^^^^^^^^^^^^^^
  File "/home/pryog/NAVODAYAN/venv/lib/python3.13/site-packages/django/contrib/admin/options.py", line 1314, in save_model
    obj.save()
    ~~~~~~~~^^
  File "/home/pryog/NAVODAYAN/venv/lib/python3.13/site-packages/django/db/models/base.py", line 902, in save
    self.save_base(
    ~~~~~~~~~~~~~~^
        using=using,
        ^^^^^^^^^^^^
    ...<2 lines>...
        update_fields=update_fields,
        ^^^^^^^^^^^^^^^^^^^^^^^^^^^^
    )
    ^
  File "/home/pryog/NAVODAYAN/venv/lib/python3.13/site-packages/django/db/models/base.py", line 1008, in save_base
    updated = self._save_table(
        raw,
    ...<4 lines>...
        update_fields,
    )
  File "/home/pryog/NAVODAYAN/venv/lib/python3.13/site-packages/django/db/models/base.py", line 1132, in _save_table
    (getattr(self, f.attname) if raw else f.pre_save(self, False)),
                                          ~~~~~~~~~~^^^^^^^^^^^^^
  File "/home/pryog/NAVODAYAN/venv/lib/python3.13/site-packages/django/db/models/fields/files.py", line 338, in pre_save
    file.save(file.name, file.file, save=False)
    ~~~~~~~~~^^^^^^^^^^^^^^^^^^^^^^^^^^^^^^^^^^
  File "/home/pryog/NAVODAYAN/venv/lib/python3.13/site-packages/django/db/models/fields/files.py", line 99, in save
    self.name = self.storage.save(name, content, max_length=self.field.max_length)
                ~~~~~~~~~~~~~~~~~^^^^^^^^^^^^^^^^^^^^^^^^^^^^^^^^^^^^^^^^^^^^^^^^^
  File "/home/pryog/NAVODAYAN/venv/lib/python3.13/site-packages/django/core/files/storage/base.py", line 49, in save
    name = self._save(name, content)
  File "/home/pryog/NAVODAYAN/venv/lib/python3.13/site-packages/django/core/files/storage/filesystem.py", line 137, in _save
    fd = os.open(full_path, open_flags, 0o666)
PermissionError: [Errno 13] Permission denied: '/home/pryog/NAVODAYAN/haminavodayaho/media/about/s1.png'
Internal Server Error: /admin/website/aboutsection/1/change/
Traceback (most recent call last):
  File "/home/pryog/NAVODAYAN/venv/lib/python3.13/site-packages/asgiref/sync.py", line 518, in thread_handler
    raise exc_info[1]
  File "/home/pryog/NAVODAYAN/venv/lib/python3.13/site-packages/django/core/handlers/exception.py", line 42, in inner
    response = await get_response(request)
               ^^^^^^^^^^^^^^^^^^^^^^^^^^^
  File "/home/pryog/NAVODAYAN/venv/lib/python3.13/site-packages/asgiref/sync.py", line 518, in thread_handler
    raise exc_info[1]
  File "/home/pryog/NAVODAYAN/venv/lib/python3.13/site-packages/django/core/handlers/base.py", line 253, in _get_response_async
    response = await wrapped_callback(
               ^^^^^^^^^^^^^^^^^^^^^^^
        request, *callback_args, **callback_kwargs
        ^^^^^^^^^^^^^^^^^^^^^^^^^^^^^^^^^^^^^^^^^^
    )
    ^
  File "/home/pryog/NAVODAYAN/venv/lib/python3.13/site-packages/asgiref/sync.py", line 468, in __call__
    ret = await asyncio.shield(exec_coro)
          ^^^^^^^^^^^^^^^^^^^^^^^^^^^^^^^
  File "/home/pryog/NAVODAYAN/venv/lib/python3.13/site-packages/asgiref/current_thread_executor.py", line 40, in run
    result = self.fn(*self.args, **self.kwargs)
  File "/home/pryog/NAVODAYAN/venv/lib/python3.13/site-packages/asgiref/sync.py", line 522, in thread_handler
    return func(*args, **kwargs)
  File "/home/pryog/NAVODAYAN/venv/lib/python3.13/site-packages/django/contrib/admin/options.py", line 719, in wrapper
    return self.admin_site.admin_view(view)(*args, **kwargs)
           ~~~~~~~~~~~~~~~~~~~~~~~~~~~~~~~~^^^^^^^^^^^^^^^^^
  File "/home/pryog/NAVODAYAN/venv/lib/python3.13/site-packages/django/utils/decorators.py", line 192, in _view_wrapper
    result = _process_exception(request, e)
  File "/home/pryog/NAVODAYAN/venv/lib/python3.13/site-packages/django/utils/decorators.py", line 190, in _view_wrapper
    response = view_func(request, *args, **kwargs)
  File "/home/pryog/NAVODAYAN/venv/lib/python3.13/site-packages/django/views/decorators/cache.py", line 80, in _view_wrapper
    response = view_func(request, *args, **kwargs)
  File "/home/pryog/NAVODAYAN/venv/lib/python3.13/site-packages/django/contrib/admin/sites.py", line 246, in inner
    return view(request, *args, **kwargs)
  File "/home/pryog/NAVODAYAN/venv/lib/python3.13/site-packages/django/contrib/admin/options.py", line 1987, in change_view
    return self.changeform_view(request, object_id, form_url, extra_context)
           ~~~~~~~~~~~~~~~~~~~~^^^^^^^^^^^^^^^^^^^^^^^^^^^^^^^^^^^^^^^^^^^^^
  File "/home/pryog/NAVODAYAN/venv/lib/python3.13/site-packages/django/utils/decorators.py", line 48, in _wrapper
    return bound_method(*args, **kwargs)
  File "/home/pryog/NAVODAYAN/venv/lib/python3.13/site-packages/django/utils/decorators.py", line 192, in _view_wrapper
    result = _process_exception(request, e)
  File "/home/pryog/NAVODAYAN/venv/lib/python3.13/site-packages/django/utils/decorators.py", line 190, in _view_wrapper
    response = view_func(request, *args, **kwargs)
  File "/home/pryog/NAVODAYAN/venv/lib/python3.13/site-packages/django/contrib/admin/options.py", line 1843, in changeform_view
    return self._changeform_view(request, object_id, form_url, extra_context)
           ~~~~~~~~~~~~~~~~~~~~~^^^^^^^^^^^^^^^^^^^^^^^^^^^^^^^^^^^^^^^^^^^^^
  File "/home/pryog/NAVODAYAN/venv/lib/python3.13/site-packages/django/contrib/admin/options.py", line 1894, in _changeform_view
    self.save_model(request, new_object, form, not add)
    ~~~~~~~~~~~~~~~^^^^^^^^^^^^^^^^^^^^^^^^^^^^^^^^^^^^
  File "/home/pryog/NAVODAYAN/venv/lib/python3.13/site-packages/django/contrib/admin/options.py", line 1314, in save_model
    obj.save()
    ~~~~~~~~^^
  File "/home/pryog/NAVODAYAN/venv/lib/python3.13/site-packages/django/db/models/base.py", line 902, in save
    self.save_base(
    ~~~~~~~~~~~~~~^
        using=using,
        ^^^^^^^^^^^^
    ...<2 lines>...
        update_fields=update_fields,
        ^^^^^^^^^^^^^^^^^^^^^^^^^^^^
    )
    ^
  File "/home/pryog/NAVODAYAN/venv/lib/python3.13/site-packages/django/db/models/base.py", line 1008, in save_base
    updated = self._save_table(
        raw,
    ...<4 lines>...
        update_fields,
    )
  File "/home/pryog/NAVODAYAN/venv/lib/python3.13/site-packages/django/db/models/base.py", line 1132, in _save_table
    (getattr(self, f.attname) if raw else f.pre_save(self, False)),
                                          ~~~~~~~~~~^^^^^^^^^^^^^
  File "/home/pryog/NAVODAYAN/venv/lib/python3.13/site-packages/django/db/models/fields/files.py", line 338, in pre_save
    file.save(file.name, file.file, save=False)
    ~~~~~~~~~^^^^^^^^^^^^^^^^^^^^^^^^^^^^^^^^^^
  File "/home/pryog/NAVODAYAN/venv/lib/python3.13/site-packages/django/db/models/fields/files.py", line 99, in save
    self.name = self.storage.save(name, content, max_length=self.field.max_length)
                ~~~~~~~~~~~~~~~~~^^^^^^^^^^^^^^^^^^^^^^^^^^^^^^^^^^^^^^^^^^^^^^^^^
  File "/home/pryog/NAVODAYAN/venv/lib/python3.13/site-packages/django/core/files/storage/base.py", line 49, in save
    name = self._save(name, content)
  File "/home/pryog/NAVODAYAN/venv/lib/python3.13/site-packages/django/core/files/storage/filesystem.py", line 137, in _save
    fd = os.open(full_path, open_flags, 0o666)
PermissionError: [Errno 13] Permission denied: '/home/pryog/NAVODAYAN/haminavodayaho/media/about/s1.1.png'
Internal Server Error: /admin/website/aboutsection/1/change/
Traceback (most recent call last):
  File "/home/pryog/NAVODAYAN/venv/lib/python3.13/site-packages/asgiref/sync.py", line 518, in thread_handler
    raise exc_info[1]
  File "/home/pryog/NAVODAYAN/venv/lib/python3.13/site-packages/django/core/handlers/exception.py", line 42, in inner
    response = await get_response(request)
               ^^^^^^^^^^^^^^^^^^^^^^^^^^^
  File "/home/pryog/NAVODAYAN/venv/lib/python3.13/site-packages/asgiref/sync.py", line 518, in thread_handler
    raise exc_info[1]
  File "/home/pryog/NAVODAYAN/venv/lib/python3.13/site-packages/django/core/handlers/base.py", line 253, in _get_response_async
    response = await wrapped_callback(
               ^^^^^^^^^^^^^^^^^^^^^^^
        request, *callback_args, **callback_kwargs
        ^^^^^^^^^^^^^^^^^^^^^^^^^^^^^^^^^^^^^^^^^^
    )
    ^
  File "/home/pryog/NAVODAYAN/venv/lib/python3.13/site-packages/asgiref/sync.py", line 468, in __call__
    ret = await asyncio.shield(exec_coro)
          ^^^^^^^^^^^^^^^^^^^^^^^^^^^^^^^
  File "/home/pryog/NAVODAYAN/venv/lib/python3.13/site-packages/asgiref/current_thread_executor.py", line 40, in run
    result = self.fn(*self.args, **self.kwargs)
  File "/home/pryog/NAVODAYAN/venv/lib/python3.13/site-packages/asgiref/sync.py", line 522, in thread_handler
    return func(*args, **kwargs)
  File "/home/pryog/NAVODAYAN/venv/lib/python3.13/site-packages/django/contrib/admin/options.py", line 719, in wrapper
    return self.admin_site.admin_view(view)(*args, **kwargs)
           ~~~~~~~~~~~~~~~~~~~~~~~~~~~~~~~~^^^^^^^^^^^^^^^^^
  File "/home/pryog/NAVODAYAN/venv/lib/python3.13/site-packages/django/utils/decorators.py", line 192, in _view_wrapper
    result = _process_exception(request, e)
  File "/home/pryog/NAVODAYAN/venv/lib/python3.13/site-packages/django/utils/decorators.py", line 190, in _view_wrapper
    response = view_func(request, *args, **kwargs)
  File "/home/pryog/NAVODAYAN/venv/lib/python3.13/site-packages/django/views/decorators/cache.py", line 80, in _view_wrapper
    response = view_func(request, *args, **kwargs)
  File "/home/pryog/NAVODAYAN/venv/lib/python3.13/site-packages/django/contrib/admin/sites.py", line 246, in inner
    return view(request, *args, **kwargs)
  File "/home/pryog/NAVODAYAN/venv/lib/python3.13/site-packages/django/contrib/admin/options.py", line 1987, in change_view
    return self.changeform_view(request, object_id, form_url, extra_context)
           ~~~~~~~~~~~~~~~~~~~~^^^^^^^^^^^^^^^^^^^^^^^^^^^^^^^^^^^^^^^^^^^^^
  File "/home/pryog/NAVODAYAN/venv/lib/python3.13/site-packages/django/utils/decorators.py", line 48, in _wrapper
    return bound_method(*args, **kwargs)
  File "/home/pryog/NAVODAYAN/venv/lib/python3.13/site-packages/django/utils/decorators.py", line 192, in _view_wrapper
    result = _process_exception(request, e)
  File "/home/pryog/NAVODAYAN/venv/lib/python3.13/site-packages/django/utils/decorators.py", line 190, in _view_wrapper
    response = view_func(request, *args, **kwargs)
  File "/home/pryog/NAVODAYAN/venv/lib/python3.13/site-packages/django/contrib/admin/options.py", line 1843, in changeform_view
    return self._changeform_view(request, object_id, form_url, extra_context)
           ~~~~~~~~~~~~~~~~~~~~~^^^^^^^^^^^^^^^^^^^^^^^^^^^^^^^^^^^^^^^^^^^^^
  File "/home/pryog/NAVODAYAN/venv/lib/python3.13/site-packages/django/contrib/admin/options.py", line 1894, in _changeform_view
    self.save_model(request, new_object, form, not add)
    ~~~~~~~~~~~~~~~^^^^^^^^^^^^^^^^^^^^^^^^^^^^^^^^^^^^
  File "/home/pryog/NAVODAYAN/venv/lib/python3.13/site-packages/django/contrib/admin/options.py", line 1314, in save_model
    obj.save()
    ~~~~~~~~^^
  File "/home/pryog/NAVODAYAN/venv/lib/python3.13/site-packages/django/db/models/base.py", line 902, in save
    self.save_base(
    ~~~~~~~~~~~~~~^
        using=using,
        ^^^^^^^^^^^^
    ...<2 lines>...
        update_fields=update_fields,
        ^^^^^^^^^^^^^^^^^^^^^^^^^^^^
    )
    ^
  File "/home/pryog/NAVODAYAN/venv/lib/python3.13/site-packages/django/db/models/base.py", line 1008, in save_base
    updated = self._save_table(
        raw,
    ...<4 lines>...
        update_fields,
    )
  File "/home/pryog/NAVODAYAN/venv/lib/python3.13/site-packages/django/db/models/base.py", line 1132, in _save_table
    (getattr(self, f.attname) if raw else f.pre_save(self, False)),
                                          ~~~~~~~~~~^^^^^^^^^^^^^
  File "/home/pryog/NAVODAYAN/venv/lib/python3.13/site-packages/django/db/models/fields/files.py", line 338, in pre_save
    file.save(file.name, file.file, save=False)
    ~~~~~~~~~^^^^^^^^^^^^^^^^^^^^^^^^^^^^^^^^^^
  File "/home/pryog/NAVODAYAN/venv/lib/python3.13/site-packages/django/db/models/fields/files.py", line 99, in save
    self.name = self.storage.save(name, content, max_length=self.field.max_length)
                ~~~~~~~~~~~~~~~~~^^^^^^^^^^^^^^^^^^^^^^^^^^^^^^^^^^^^^^^^^^^^^^^^^
  File "/home/pryog/NAVODAYAN/venv/lib/python3.13/site-packages/django/core/files/storage/base.py", line 49, in save
    name = self._save(name, content)
  File "/home/pryog/NAVODAYAN/venv/lib/python3.13/site-packages/django/core/files/storage/filesystem.py", line 137, in _save
    fd = os.open(full_path, open_flags, 0o666)
PermissionError: [Errno 13] Permission denied: '/home/pryog/NAVODAYAN/haminavodayaho/media/about/s1.1.png'
Internal Server Error: /admin/website/myapkfile/add/
Traceback (most recent call last):
  File "/home/pryog/NAVODAYAN/venv/lib/python3.13/site-packages/django/core/handlers/exception.py", line 55, in inner
    response = get_response(request)
  File "/home/pryog/NAVODAYAN/venv/lib/python3.13/site-packages/django/core/handlers/base.py", line 197, in _get_response
    response = wrapped_callback(request, *callback_args, **callback_kwargs)
  File "/home/pryog/NAVODAYAN/venv/lib/python3.13/site-packages/django/contrib/admin/options.py", line 719, in wrapper
    return self.admin_site.admin_view(view)(*args, **kwargs)
           ~~~~~~~~~~~~~~~~~~~~~~~~~~~~~~~~^^^^^^^^^^^^^^^^^
  File "/home/pryog/NAVODAYAN/venv/lib/python3.13/site-packages/django/utils/decorators.py", line 192, in _view_wrapper
    result = _process_exception(request, e)
  File "/home/pryog/NAVODAYAN/venv/lib/python3.13/site-packages/django/utils/decorators.py", line 190, in _view_wrapper
    response = view_func(request, *args, **kwargs)
  File "/home/pryog/NAVODAYAN/venv/lib/python3.13/site-packages/django/views/decorators/cache.py", line 80, in _view_wrapper
    response = view_func(request, *args, **kwargs)
  File "/home/pryog/NAVODAYAN/venv/lib/python3.13/site-packages/django/contrib/admin/sites.py", line 246, in inner
    return view(request, *args, **kwargs)
  File "/home/pryog/NAVODAYAN/venv/lib/python3.13/site-packages/django/contrib/admin/options.py", line 1984, in add_view
    return self.changeform_view(request, None, form_url, extra_context)
           ~~~~~~~~~~~~~~~~~~~~^^^^^^^^^^^^^^^^^^^^^^^^^^^^^^^^^^^^^^^^
  File "/home/pryog/NAVODAYAN/venv/lib/python3.13/site-packages/django/utils/decorators.py", line 48, in _wrapper
    return bound_method(*args, **kwargs)
  File "/home/pryog/NAVODAYAN/venv/lib/python3.13/site-packages/django/utils/decorators.py", line 192, in _view_wrapper
    result = _process_exception(request, e)
  File "/home/pryog/NAVODAYAN/venv/lib/python3.13/site-packages/django/utils/decorators.py", line 190, in _view_wrapper
    response = view_func(request, *args, **kwargs)
  File "/home/pryog/NAVODAYAN/venv/lib/python3.13/site-packages/django/contrib/admin/options.py", line 1843, in changeform_view
    return self._changeform_view(request, object_id, form_url, extra_context)
           ~~~~~~~~~~~~~~~~~~~~~^^^^^^^^^^^^^^^^^^^^^^^^^^^^^^^^^^^^^^^^^^^^^
  File "/home/pryog/NAVODAYAN/venv/lib/python3.13/site-packages/django/contrib/admin/options.py", line 1894, in _changeform_view
    self.save_model(request, new_object, form, not add)
    ~~~~~~~~~~~~~~~^^^^^^^^^^^^^^^^^^^^^^^^^^^^^^^^^^^^
  File "/home/pryog/NAVODAYAN/venv/lib/python3.13/site-packages/django/contrib/admin/options.py", line 1314, in save_model
    obj.save()
    ~~~~~~~~^^
  File "/home/pryog/NAVODAYAN/venv/lib/python3.13/site-packages/django/db/models/base.py", line 902, in save
    self.save_base(
    ~~~~~~~~~~~~~~^
        using=using,
        ^^^^^^^^^^^^
    ...<2 lines>...
        update_fields=update_fields,
        ^^^^^^^^^^^^^^^^^^^^^^^^^^^^
    )
    ^
  File "/home/pryog/NAVODAYAN/venv/lib/python3.13/site-packages/django/db/models/base.py", line 1008, in save_base
    updated = self._save_table(
        raw,
    ...<4 lines>...
        update_fields,
    )
  File "/home/pryog/NAVODAYAN/venv/lib/python3.13/site-packages/django/db/models/base.py", line 1169, in _save_table
    results = self._do_insert(
        cls._base_manager, using, fields, returning_fields, raw
    )
  File "/home/pryog/NAVODAYAN/venv/lib/python3.13/site-packages/django/db/models/base.py", line 1210, in _do_insert
    return manager._insert(
           ~~~~~~~~~~~~~~~^
        [self],
        ^^^^^^^
    ...<3 lines>...
        raw=raw,
        ^^^^^^^^
    )
    ^
  File "/home/pryog/NAVODAYAN/venv/lib/python3.13/site-packages/django/db/models/manager.py", line 87, in manager_method
    return getattr(self.get_queryset(), name)(*args, **kwargs)
           ~~~~~~~~~~~~~~~~~~~~~~~~~~~~~~~~~~^^^^^^^^^^^^^^^^^
  File "/home/pryog/NAVODAYAN/venv/lib/python3.13/site-packages/django/db/models/query.py", line 1854, in _insert
    return query.get_compiler(using=using).execute_sql(returning_fields)
           ~~~~~~~~~~~~~~~~~~~~~~~~~~~~~~~~~~~~~~~~~~~^^^^^^^^^^^^^^^^^^
  File "/home/pryog/NAVODAYAN/venv/lib/python3.13/site-packages/django/db/models/sql/compiler.py", line 1880, in execute_sql
    for sql, params in self.as_sql():
                       ~~~~~~~~~~~^^
  File "/home/pryog/NAVODAYAN/venv/lib/python3.13/site-packages/django/db/models/sql/compiler.py", line 1805, in as_sql
    self.prepare_value(field, self.pre_save_val(field, obj))
                              ~~~~~~~~~~~~~~~~~^^^^^^^^^^^^
  File "/home/pryog/NAVODAYAN/venv/lib/python3.13/site-packages/django/db/models/sql/compiler.py", line 1749, in pre_save_val
    return field.pre_save(obj, add=True)
           ~~~~~~~~~~~~~~^^^^^^^^^^^^^^^
  File "/home/pryog/NAVODAYAN/venv/lib/python3.13/site-packages/django/db/models/fields/files.py", line 338, in pre_save
    file.save(file.name, file.file, save=False)
    ~~~~~~~~~^^^^^^^^^^^^^^^^^^^^^^^^^^^^^^^^^^
  File "/home/pryog/NAVODAYAN/venv/lib/python3.13/site-packages/django/db/models/fields/files.py", line 99, in save
    self.name = self.storage.save(name, content, max_length=self.field.max_length)
                ~~~~~~~~~~~~~~~~~^^^^^^^^^^^^^^^^^^^^^^^^^^^^^^^^^^^^^^^^^^^^^^^^^
  File "/home/pryog/NAVODAYAN/venv/lib/python3.13/site-packages/django/core/files/storage/base.py", line 49, in save
    name = self._save(name, content)
  File "/home/pryog/NAVODAYAN/venv/lib/python3.13/site-packages/django/core/files/storage/filesystem.py", line 100, in _save
    os.makedirs(directory, exist_ok=True)
    ~~~~~~~~~~~^^^^^^^^^^^^^^^^^^^^^^^^^^
  File "<frozen os>", line 227, in makedirs
PermissionError: [Errno 13] Permission denied: '/home/pryog/NAVODAYAN/haminavodayaho/media/apk'
"POST /admin/website/myapkfile/add/ HTTP/1.1" 500 145
Internal Server Error: /admin/website/myapkfile/add/
Traceback (most recent call last):
  File "/home/pryog/NAVODAYAN/venv/lib/python3.13/site-packages/django/core/handlers/exception.py", line 55, in inner
    response = get_response(request)
  File "/home/pryog/NAVODAYAN/venv/lib/python3.13/site-packages/django/core/handlers/base.py", line 197, in _get_response
    response = wrapped_callback(request, *callback_args, **callback_kwargs)
  File "/home/pryog/NAVODAYAN/venv/lib/python3.13/site-packages/django/contrib/admin/options.py", line 719, in wrapper
    return self.admin_site.admin_view(view)(*args, **kwargs)
           ~~~~~~~~~~~~~~~~~~~~~~~~~~~~~~~~^^^^^^^^^^^^^^^^^
  File "/home/pryog/NAVODAYAN/venv/lib/python3.13/site-packages/django/utils/decorators.py", line 192, in _view_wrapper
    result = _process_exception(request, e)
  File "/home/pryog/NAVODAYAN/venv/lib/python3.13/site-packages/django/utils/decorators.py", line 190, in _view_wrapper
    response = view_func(request, *args, **kwargs)
  File "/home/pryog/NAVODAYAN/venv/lib/python3.13/site-packages/django/views/decorators/cache.py", line 80, in _view_wrapper
    response = view_func(request, *args, **kwargs)
  File "/home/pryog/NAVODAYAN/venv/lib/python3.13/site-packages/django/contrib/admin/sites.py", line 246, in inner
    return view(request, *args, **kwargs)
  File "/home/pryog/NAVODAYAN/venv/lib/python3.13/site-packages/django/contrib/admin/options.py", line 1984, in add_view
    return self.changeform_view(request, None, form_url, extra_context)
           ~~~~~~~~~~~~~~~~~~~~^^^^^^^^^^^^^^^^^^^^^^^^^^^^^^^^^^^^^^^^
  File "/home/pryog/NAVODAYAN/venv/lib/python3.13/site-packages/django/utils/decorators.py", line 48, in _wrapper
    return bound_method(*args, **kwargs)
  File "/home/pryog/NAVODAYAN/venv/lib/python3.13/site-packages/django/utils/decorators.py", line 192, in _view_wrapper
    result = _process_exception(request, e)
  File "/home/pryog/NAVODAYAN/venv/lib/python3.13/site-packages/django/utils/decorators.py", line 190, in _view_wrapper
    response = view_func(request, *args, **kwargs)
  File "/home/pryog/NAVODAYAN/venv/lib/python3.13/site-packages/django/contrib/admin/options.py", line 1843, in changeform_view
    return self._changeform_view(request, object_id, form_url, extra_context)
           ~~~~~~~~~~~~~~~~~~~~~^^^^^^^^^^^^^^^^^^^^^^^^^^^^^^^^^^^^^^^^^^^^^
  File "/home/pryog/NAVODAYAN/venv/lib/python3.13/site-packages/django/contrib/admin/options.py", line 1894, in _changeform_view
    self.save_model(request, new_object, form, not add)
    ~~~~~~~~~~~~~~~^^^^^^^^^^^^^^^^^^^^^^^^^^^^^^^^^^^^
  File "/home/pryog/NAVODAYAN/venv/lib/python3.13/site-packages/django/contrib/admin/options.py", line 1314, in save_model
    obj.save()
    ~~~~~~~~^^
  File "/home/pryog/NAVODAYAN/venv/lib/python3.13/site-packages/django/db/models/base.py", line 902, in save
    self.save_base(
    ~~~~~~~~~~~~~~^
        using=using,
        ^^^^^^^^^^^^
    ...<2 lines>...
        update_fields=update_fields,
        ^^^^^^^^^^^^^^^^^^^^^^^^^^^^
    )
    ^
  File "/home/pryog/NAVODAYAN/venv/lib/python3.13/site-packages/django/db/models/base.py", line 1008, in save_base
    updated = self._save_table(
        raw,
    ...<4 lines>...
        update_fields,
    )
  File "/home/pryog/NAVODAYAN/venv/lib/python3.13/site-packages/django/db/models/base.py", line 1169, in _save_table
    results = self._do_insert(
        cls._base_manager, using, fields, returning_fields, raw
    )
  File "/home/pryog/NAVODAYAN/venv/lib/python3.13/site-packages/django/db/models/base.py", line 1210, in _do_insert
    return manager._insert(
           ~~~~~~~~~~~~~~~^
        [self],
        ^^^^^^^
    ...<3 lines>...
        raw=raw,
        ^^^^^^^^
    )
    ^
  File "/home/pryog/NAVODAYAN/venv/lib/python3.13/site-packages/django/db/models/manager.py", line 87, in manager_method
    return getattr(self.get_queryset(), name)(*args, **kwargs)
           ~~~~~~~~~~~~~~~~~~~~~~~~~~~~~~~~~~^^^^^^^^^^^^^^^^^
  File "/home/pryog/NAVODAYAN/venv/lib/python3.13/site-packages/django/db/models/query.py", line 1854, in _insert
    return query.get_compiler(using=using).execute_sql(returning_fields)
           ~~~~~~~~~~~~~~~~~~~~~~~~~~~~~~~~~~~~~~~~~~~^^^^^^^^^^^^^^^^^^
  File "/home/pryog/NAVODAYAN/venv/lib/python3.13/site-packages/django/db/models/sql/compiler.py", line 1880, in execute_sql
    for sql, params in self.as_sql():
                       ~~~~~~~~~~~^^
  File "/home/pryog/NAVODAYAN/venv/lib/python3.13/site-packages/django/db/models/sql/compiler.py", line 1805, in as_sql
    self.prepare_value(field, self.pre_save_val(field, obj))
                              ~~~~~~~~~~~~~~~~~^^^^^^^^^^^^
  File "/home/pryog/NAVODAYAN/venv/lib/python3.13/site-packages/django/db/models/sql/compiler.py", line 1749, in pre_save_val
    return field.pre_save(obj, add=True)
           ~~~~~~~~~~~~~~^^^^^^^^^^^^^^^
  File "/home/pryog/NAVODAYAN/venv/lib/python3.13/site-packages/django/db/models/fields/files.py", line 338, in pre_save
    file.save(file.name, file.file, save=False)
    ~~~~~~~~~^^^^^^^^^^^^^^^^^^^^^^^^^^^^^^^^^^
  File "/home/pryog/NAVODAYAN/venv/lib/python3.13/site-packages/django/db/models/fields/files.py", line 99, in save
    self.name = self.storage.save(name, content, max_length=self.field.max_length)
                ~~~~~~~~~~~~~~~~~^^^^^^^^^^^^^^^^^^^^^^^^^^^^^^^^^^^^^^^^^^^^^^^^^
  File "/home/pryog/NAVODAYAN/venv/lib/python3.13/site-packages/django/core/files/storage/base.py", line 49, in save
    name = self._save(name, content)
  File "/home/pryog/NAVODAYAN/venv/lib/python3.13/site-packages/django/core/files/storage/filesystem.py", line 100, in _save
    os.makedirs(directory, exist_ok=True)
    ~~~~~~~~~~~^^^^^^^^^^^^^^^^^^^^^^^^^^
  File "<frozen os>", line 227, in makedirs
PermissionError: [Errno 13] Permission denied: '/home/pryog/NAVODAYAN/haminavodayaho/media/apk'
"POST /admin/website/myapkfile/add/ HTTP/1.1" 500 192799
Internal Server Error: /admin/website/myapkfile/add/
Traceback (most recent call last):
  File "/home/pryog/NAVODAYAN/venv/lib/python3.13/site-packages/django/core/handlers/exception.py", line 55, in inner
    response = get_response(request)
  File "/home/pryog/NAVODAYAN/venv/lib/python3.13/site-packages/django/core/handlers/base.py", line 197, in _get_response
    response = wrapped_callback(request, *callback_args, **callback_kwargs)
  File "/home/pryog/NAVODAYAN/venv/lib/python3.13/site-packages/django/contrib/admin/options.py", line 719, in wrapper
    return self.admin_site.admin_view(view)(*args, **kwargs)
           ~~~~~~~~~~~~~~~~~~~~~~~~~~~~~~~~^^^^^^^^^^^^^^^^^
  File "/home/pryog/NAVODAYAN/venv/lib/python3.13/site-packages/django/utils/decorators.py", line 192, in _view_wrapper
    result = _process_exception(request, e)
  File "/home/pryog/NAVODAYAN/venv/lib/python3.13/site-packages/django/utils/decorators.py", line 190, in _view_wrapper
    response = view_func(request, *args, **kwargs)
  File "/home/pryog/NAVODAYAN/venv/lib/python3.13/site-packages/django/views/decorators/cache.py", line 80, in _view_wrapper
    response = view_func(request, *args, **kwargs)
  File "/home/pryog/NAVODAYAN/venv/lib/python3.13/site-packages/django/contrib/admin/sites.py", line 246, in inner
    return view(request, *args, **kwargs)
  File "/home/pryog/NAVODAYAN/venv/lib/python3.13/site-packages/django/contrib/admin/options.py", line 1984, in add_view
    return self.changeform_view(request, None, form_url, extra_context)
           ~~~~~~~~~~~~~~~~~~~~^^^^^^^^^^^^^^^^^^^^^^^^^^^^^^^^^^^^^^^^
  File "/home/pryog/NAVODAYAN/venv/lib/python3.13/site-packages/django/utils/decorators.py", line 48, in _wrapper
    return bound_method(*args, **kwargs)
  File "/home/pryog/NAVODAYAN/venv/lib/python3.13/site-packages/django/utils/decorators.py", line 192, in _view_wrapper
    result = _process_exception(request, e)
  File "/home/pryog/NAVODAYAN/venv/lib/python3.13/site-packages/django/utils/decorators.py", line 190, in _view_wrapper
    response = view_func(request, *args, **kwargs)
  File "/home/pryog/NAVODAYAN/venv/lib/python3.13/site-packages/django/contrib/admin/options.py", line 1843, in changeform_view
    return self._changeform_view(request, object_id, form_url, extra_context)
           ~~~~~~~~~~~~~~~~~~~~~^^^^^^^^^^^^^^^^^^^^^^^^^^^^^^^^^^^^^^^^^^^^^
  File "/home/pryog/NAVODAYAN/venv/lib/python3.13/site-packages/django/contrib/admin/options.py", line 1894, in _changeform_view
    self.save_model(request, new_object, form, not add)
    ~~~~~~~~~~~~~~~^^^^^^^^^^^^^^^^^^^^^^^^^^^^^^^^^^^^
  File "/home/pryog/NAVODAYAN/venv/lib/python3.13/site-packages/django/contrib/admin/options.py", line 1314, in save_model
    obj.save()
    ~~~~~~~~^^
  File "/home/pryog/NAVODAYAN/venv/lib/python3.13/site-packages/django/db/models/base.py", line 902, in save
    self.save_base(
    ~~~~~~~~~~~~~~^
        using=using,
        ^^^^^^^^^^^^
    ...<2 lines>...
        update_fields=update_fields,
        ^^^^^^^^^^^^^^^^^^^^^^^^^^^^
    )
    ^
  File "/home/pryog/NAVODAYAN/venv/lib/python3.13/site-packages/django/db/models/base.py", line 1008, in save_base
    updated = self._save_table(
        raw,
    ...<4 lines>...
        update_fields,
    )
  File "/home/pryog/NAVODAYAN/venv/lib/python3.13/site-packages/django/db/models/base.py", line 1169, in _save_table
    results = self._do_insert(
        cls._base_manager, using, fields, returning_fields, raw
    )
  File "/home/pryog/NAVODAYAN/venv/lib/python3.13/site-packages/django/db/models/base.py", line 1210, in _do_insert
    return manager._insert(
           ~~~~~~~~~~~~~~~^
        [self],
        ^^^^^^^
    ...<3 lines>...
        raw=raw,
        ^^^^^^^^
    )
    ^
  File "/home/pryog/NAVODAYAN/venv/lib/python3.13/site-packages/django/db/models/manager.py", line 87, in manager_method
    return getattr(self.get_queryset(), name)(*args, **kwargs)
           ~~~~~~~~~~~~~~~~~~~~~~~~~~~~~~~~~~^^^^^^^^^^^^^^^^^
  File "/home/pryog/NAVODAYAN/venv/lib/python3.13/site-packages/django/db/models/query.py", line 1854, in _insert
    return query.get_compiler(using=using).execute_sql(returning_fields)
           ~~~~~~~~~~~~~~~~~~~~~~~~~~~~~~~~~~~~~~~~~~~^^^^^^^^^^^^^^^^^^
  File "/home/pryog/NAVODAYAN/venv/lib/python3.13/site-packages/django/db/models/sql/compiler.py", line 1880, in execute_sql
    for sql, params in self.as_sql():
                       ~~~~~~~~~~~^^
  File "/home/pryog/NAVODAYAN/venv/lib/python3.13/site-packages/django/db/models/sql/compiler.py", line 1805, in as_sql
    self.prepare_value(field, self.pre_save_val(field, obj))
                              ~~~~~~~~~~~~~~~~~^^^^^^^^^^^^
  File "/home/pryog/NAVODAYAN/venv/lib/python3.13/site-packages/django/db/models/sql/compiler.py", line 1749, in pre_save_val
    return field.pre_save(obj, add=True)
           ~~~~~~~~~~~~~~^^^^^^^^^^^^^^^
  File "/home/pryog/NAVODAYAN/venv/lib/python3.13/site-packages/django/db/models/fields/files.py", line 338, in pre_save
    file.save(file.name, file.file, save=False)
    ~~~~~~~~~^^^^^^^^^^^^^^^^^^^^^^^^^^^^^^^^^^
  File "/home/pryog/NAVODAYAN/venv/lib/python3.13/site-packages/django/db/models/fields/files.py", line 99, in save
    self.name = self.storage.save(name, content, max_length=self.field.max_length)
                ~~~~~~~~~~~~~~~~~^^^^^^^^^^^^^^^^^^^^^^^^^^^^^^^^^^^^^^^^^^^^^^^^^
  File "/home/pryog/NAVODAYAN/venv/lib/python3.13/site-packages/django/core/files/storage/base.py", line 49, in save
    name = self._save(name, content)
  File "/home/pryog/NAVODAYAN/venv/lib/python3.13/site-packages/django/core/files/storage/filesystem.py", line 137, in _save
    fd = os.open(full_path, open_flags, 0o666)
PermissionError: [Errno 13] Permission denied: '/home/pryog/NAVODAYAN/haminavodayaho/media/apk/hamiNavodayaHo.svg'
"POST /admin/website/myapkfile/add/ HTTP/1.1" 500 191250
Internal Server Error: /admin/website/myapkfile/add/
Traceback (most recent call last):
  File "/home/pryog/NAVODAYAN/venv/lib/python3.13/site-packages/asgiref/sync.py", line 518, in thread_handler
    raise exc_info[1]
  File "/home/pryog/NAVODAYAN/venv/lib/python3.13/site-packages/django/core/handlers/exception.py", line 42, in inner
    response = await get_response(request)
               ^^^^^^^^^^^^^^^^^^^^^^^^^^^
  File "/home/pryog/NAVODAYAN/venv/lib/python3.13/site-packages/asgiref/sync.py", line 518, in thread_handler
    raise exc_info[1]
  File "/home/pryog/NAVODAYAN/venv/lib/python3.13/site-packages/django/core/handlers/base.py", line 253, in _get_response_async
    response = await wrapped_callback(
               ^^^^^^^^^^^^^^^^^^^^^^^
        request, *callback_args, **callback_kwargs
        ^^^^^^^^^^^^^^^^^^^^^^^^^^^^^^^^^^^^^^^^^^
    )
    ^
  File "/home/pryog/NAVODAYAN/venv/lib/python3.13/site-packages/asgiref/sync.py", line 468, in __call__
    ret = await asyncio.shield(exec_coro)
          ^^^^^^^^^^^^^^^^^^^^^^^^^^^^^^^
  File "/home/pryog/NAVODAYAN/venv/lib/python3.13/site-packages/asgiref/current_thread_executor.py", line 40, in run
    result = self.fn(*self.args, **self.kwargs)
  File "/home/pryog/NAVODAYAN/venv/lib/python3.13/site-packages/asgiref/sync.py", line 522, in thread_handler
    return func(*args, **kwargs)
  File "/home/pryog/NAVODAYAN/venv/lib/python3.13/site-packages/django/contrib/admin/options.py", line 719, in wrapper
    return self.admin_site.admin_view(view)(*args, **kwargs)
           ~~~~~~~~~~~~~~~~~~~~~~~~~~~~~~~~^^^^^^^^^^^^^^^^^
  File "/home/pryog/NAVODAYAN/venv/lib/python3.13/site-packages/django/utils/decorators.py", line 192, in _view_wrapper
    result = _process_exception(request, e)
  File "/home/pryog/NAVODAYAN/venv/lib/python3.13/site-packages/django/utils/decorators.py", line 190, in _view_wrapper
    response = view_func(request, *args, **kwargs)
  File "/home/pryog/NAVODAYAN/venv/lib/python3.13/site-packages/django/views/decorators/cache.py", line 80, in _view_wrapper
    response = view_func(request, *args, **kwargs)
  File "/home/pryog/NAVODAYAN/venv/lib/python3.13/site-packages/django/contrib/admin/sites.py", line 246, in inner
    return view(request, *args, **kwargs)
  File "/home/pryog/NAVODAYAN/venv/lib/python3.13/site-packages/django/contrib/admin/options.py", line 1984, in add_view
    return self.changeform_view(request, None, form_url, extra_context)
           ~~~~~~~~~~~~~~~~~~~~^^^^^^^^^^^^^^^^^^^^^^^^^^^^^^^^^^^^^^^^
  File "/home/pryog/NAVODAYAN/venv/lib/python3.13/site-packages/django/utils/decorators.py", line 48, in _wrapper
    return bound_method(*args, **kwargs)
  File "/home/pryog/NAVODAYAN/venv/lib/python3.13/site-packages/django/utils/decorators.py", line 192, in _view_wrapper
    result = _process_exception(request, e)
  File "/home/pryog/NAVODAYAN/venv/lib/python3.13/site-packages/django/utils/decorators.py", line 190, in _view_wrapper
    response = view_func(request, *args, **kwargs)
  File "/home/pryog/NAVODAYAN/venv/lib/python3.13/site-packages/django/contrib/admin/options.py", line 1843, in changeform_view
    return self._changeform_view(request, object_id, form_url, extra_context)
           ~~~~~~~~~~~~~~~~~~~~~^^^^^^^^^^^^^^^^^^^^^^^^^^^^^^^^^^^^^^^^^^^^^
  File "/home/pryog/NAVODAYAN/venv/lib/python3.13/site-packages/django/contrib/admin/options.py", line 1894, in _changeform_view
    self.save_model(request, new_object, form, not add)
    ~~~~~~~~~~~~~~~^^^^^^^^^^^^^^^^^^^^^^^^^^^^^^^^^^^^
  File "/home/pryog/NAVODAYAN/venv/lib/python3.13/site-packages/django/contrib/admin/options.py", line 1314, in save_model
    obj.save()
    ~~~~~~~~^^
  File "/home/pryog/NAVODAYAN/venv/lib/python3.13/site-packages/django/db/models/base.py", line 902, in save
    self.save_base(
    ~~~~~~~~~~~~~~^
        using=using,
        ^^^^^^^^^^^^
    ...<2 lines>...
        update_fields=update_fields,
        ^^^^^^^^^^^^^^^^^^^^^^^^^^^^
    )
    ^
  File "/home/pryog/NAVODAYAN/venv/lib/python3.13/site-packages/django/db/models/base.py", line 1008, in save_base
    updated = self._save_table(
        raw,
    ...<4 lines>...
        update_fields,
    )
  File "/home/pryog/NAVODAYAN/venv/lib/python3.13/site-packages/django/db/models/base.py", line 1169, in _save_table
    results = self._do_insert(
        cls._base_manager, using, fields, returning_fields, raw
    )
  File "/home/pryog/NAVODAYAN/venv/lib/python3.13/site-packages/django/db/models/base.py", line 1210, in _do_insert
    return manager._insert(
           ~~~~~~~~~~~~~~~^
        [self],
        ^^^^^^^
    ...<3 lines>...
        raw=raw,
        ^^^^^^^^
    )
    ^
  File "/home/pryog/NAVODAYAN/venv/lib/python3.13/site-packages/django/db/models/manager.py", line 87, in manager_method
    return getattr(self.get_queryset(), name)(*args, **kwargs)
           ~~~~~~~~~~~~~~~~~~~~~~~~~~~~~~~~~~^^^^^^^^^^^^^^^^^
  File "/home/pryog/NAVODAYAN/venv/lib/python3.13/site-packages/django/db/models/query.py", line 1854, in _insert
    return query.get_compiler(using=using).execute_sql(returning_fields)
           ~~~~~~~~~~~~~~~~~~~~~~~~~~~~~~~~~~~~~~~~~~~^^^^^^^^^^^^^^^^^^
  File "/home/pryog/NAVODAYAN/venv/lib/python3.13/site-packages/django/db/models/sql/compiler.py", line 1880, in execute_sql
    for sql, params in self.as_sql():
                       ~~~~~~~~~~~^^
  File "/home/pryog/NAVODAYAN/venv/lib/python3.13/site-packages/django/db/models/sql/compiler.py", line 1805, in as_sql
    self.prepare_value(field, self.pre_save_val(field, obj))
                              ~~~~~~~~~~~~~~~~~^^^^^^^^^^^^
  File "/home/pryog/NAVODAYAN/venv/lib/python3.13/site-packages/django/db/models/sql/compiler.py", line 1749, in pre_save_val
    return field.pre_save(obj, add=True)
           ~~~~~~~~~~~~~~^^^^^^^^^^^^^^^
  File "/home/pryog/NAVODAYAN/venv/lib/python3.13/site-packages/django/db/models/fields/files.py", line 338, in pre_save
    file.save(file.name, file.file, save=False)
    ~~~~~~~~~^^^^^^^^^^^^^^^^^^^^^^^^^^^^^^^^^^
  File "/home/pryog/NAVODAYAN/venv/lib/python3.13/site-packages/django/db/models/fields/files.py", line 99, in save
    self.name = self.storage.save(name, content, max_length=self.field.max_length)
                ~~~~~~~~~~~~~~~~~^^^^^^^^^^^^^^^^^^^^^^^^^^^^^^^^^^^^^^^^^^^^^^^^^
  File "/home/pryog/NAVODAYAN/venv/lib/python3.13/site-packages/django/core/files/storage/base.py", line 49, in save
    name = self._save(name, content)
  File "/home/pryog/NAVODAYAN/venv/lib/python3.13/site-packages/django/core/files/storage/filesystem.py", line 137, in _save
    fd = os.open(full_path, open_flags, 0o666)
PermissionError: [Errno 13] Permission denied: '/home/pryog/NAVODAYAN/haminavodayaho/media/apk/hamiNavodayaHo.svg'
Internal Server Error: /
Traceback (most recent call last):
  File "/home/pryog/NAVODAYAN/venv/lib/python3.13/site-packages/django/template/base.py", line 510, in parse
    compile_func = self.tags[command]
                   ~~~~~~~~~^^^^^^^^^
KeyError: '{%'

During handling of the above exception, another exception occurred:

Traceback (most recent call last):
  File "/home/pryog/NAVODAYAN/venv/lib/python3.13/site-packages/asgiref/sync.py", line 518, in thread_handler
    raise exc_info[1]
  File "/home/pryog/NAVODAYAN/venv/lib/python3.13/site-packages/django/core/handlers/exception.py", line 42, in inner
    response = await get_response(request)
               ^^^^^^^^^^^^^^^^^^^^^^^^^^^
  File "/home/pryog/NAVODAYAN/venv/lib/python3.13/site-packages/asgiref/sync.py", line 518, in thread_handler
    raise exc_info[1]
  File "/home/pryog/NAVODAYAN/venv/lib/python3.13/site-packages/django/core/handlers/base.py", line 253, in _get_response_async
    response = await wrapped_callback(
               ^^^^^^^^^^^^^^^^^^^^^^^
        request, *callback_args, **callback_kwargs
        ^^^^^^^^^^^^^^^^^^^^^^^^^^^^^^^^^^^^^^^^^^
    )
    ^
  File "/home/pryog/NAVODAYAN/venv/lib/python3.13/site-packages/asgiref/sync.py", line 468, in __call__
    ret = await asyncio.shield(exec_coro)
          ^^^^^^^^^^^^^^^^^^^^^^^^^^^^^^^
  File "/home/pryog/NAVODAYAN/venv/lib/python3.13/site-packages/asgiref/current_thread_executor.py", line 40, in run
    result = self.fn(*self.args, **self.kwargs)
  File "/home/pryog/NAVODAYAN/venv/lib/python3.13/site-packages/asgiref/sync.py", line 522, in thread_handler
    return func(*args, **kwargs)
  File "/home/pryog/NAVODAYAN/haminavodayaho/website/views.py", line 16, in index
    return render(request, 'website/index.html', context)
  File "/home/pryog/NAVODAYAN/venv/lib/python3.13/site-packages/django/shortcuts.py", line 25, in render
    content = loader.render_to_string(template_name, context, request, using=using)
  File "/home/pryog/NAVODAYAN/venv/lib/python3.13/site-packages/django/template/loader.py", line 61, in render_to_string
    template = get_template(template_name, using=using)
  File "/home/pryog/NAVODAYAN/venv/lib/python3.13/site-packages/django/template/loader.py", line 15, in get_template
    return engine.get_template(template_name)
           ~~~~~~~~~~~~~~~~~~~^^^^^^^^^^^^^^^
  File "/home/pryog/NAVODAYAN/venv/lib/python3.13/site-packages/django/template/backends/django.py", line 79, in get_template
    return Template(self.engine.get_template(template_name), self)
                    ~~~~~~~~~~~~~~~~~~~~~~~~^^^^^^^^^^^^^^^
  File "/home/pryog/NAVODAYAN/venv/lib/python3.13/site-packages/django/template/engine.py", line 177, in get_template
    template, origin = self.find_template(template_name)
                       ~~~~~~~~~~~~~~~~~~^^^^^^^^^^^^^^^
  File "/home/pryog/NAVODAYAN/venv/lib/python3.13/site-packages/django/template/engine.py", line 159, in find_template
    template = loader.get_template(name, skip=skip)
  File "/home/pryog/NAVODAYAN/venv/lib/python3.13/site-packages/django/template/loaders/cached.py", line 57, in get_template
    template = super().get_template(template_name, skip)
  File "/home/pryog/NAVODAYAN/venv/lib/python3.13/site-packages/django/template/loaders/base.py", line 28, in get_template
    return Template(
        contents,
    ...<2 lines>...
        self.engine,
    )
  File "/home/pryog/NAVODAYAN/venv/lib/python3.13/site-packages/django/template/base.py", line 154, in __init__
    self.nodelist = self.compile_nodelist()
                    ~~~~~~~~~~~~~~~~~~~~~^^
  File "/home/pryog/NAVODAYAN/venv/lib/python3.13/site-packages/django/template/base.py", line 196, in compile_nodelist
    nodelist = parser.parse()
  File "/home/pryog/NAVODAYAN/venv/lib/python3.13/site-packages/django/template/base.py", line 512, in parse
    self.invalid_block_tag(token, command, parse_until)
    ~~~~~~~~~~~~~~~~~~~~~~^^^^^^^^^^^^^^^^^^^^^^^^^^^^^
  File "/home/pryog/NAVODAYAN/venv/lib/python3.13/site-packages/django/template/base.py", line 577, in invalid_block_tag
    raise self.error(
    ...<3 lines>...
    )
django.template.exceptions.TemplateSyntaxError: Invalid block tag on line 103: '{%'. Did you forget to register or load this tag?
Internal Server Error: /
Traceback (most recent call last):
  File "/home/pryog/NAVODAYAN/venv/lib/python3.13/site-packages/asgiref/sync.py", line 518, in thread_handler
    raise exc_info[1]
  File "/home/pryog/NAVODAYAN/venv/lib/python3.13/site-packages/django/core/handlers/exception.py", line 42, in inner
    response = await get_response(request)
               ^^^^^^^^^^^^^^^^^^^^^^^^^^^
  File "/home/pryog/NAVODAYAN/venv/lib/python3.13/site-packages/asgiref/sync.py", line 518, in thread_handler
    raise exc_info[1]
  File "/home/pryog/NAVODAYAN/venv/lib/python3.13/site-packages/django/core/handlers/base.py", line 253, in _get_response_async
    response = await wrapped_callback(
               ^^^^^^^^^^^^^^^^^^^^^^^
        request, *callback_args, **callback_kwargs
        ^^^^^^^^^^^^^^^^^^^^^^^^^^^^^^^^^^^^^^^^^^
    )
    ^
  File "/home/pryog/NAVODAYAN/venv/lib/python3.13/site-packages/asgiref/sync.py", line 468, in __call__
    ret = await asyncio.shield(exec_coro)
          ^^^^^^^^^^^^^^^^^^^^^^^^^^^^^^^
  File "/home/pryog/NAVODAYAN/venv/lib/python3.13/site-packages/asgiref/current_thread_executor.py", line 40, in run
    result = self.fn(*self.args, **self.kwargs)
  File "/home/pryog/NAVODAYAN/venv/lib/python3.13/site-packages/asgiref/sync.py", line 522, in thread_handler
    return func(*args, **kwargs)
  File "/home/pryog/NAVODAYAN/haminavodayaho/website/views.py", line 16, in index
    return render(request, 'website/index.html', context)
  File "/home/pryog/NAVODAYAN/venv/lib/python3.13/site-packages/django/shortcuts.py", line 25, in render
    content = loader.render_to_string(template_name, context, request, using=using)
  File "/home/pryog/NAVODAYAN/venv/lib/python3.13/site-packages/django/template/loader.py", line 62, in render_to_string
    return template.render(context, request)
           ~~~~~~~~~~~~~~~^^^^^^^^^^^^^^^^^^
  File "/home/pryog/NAVODAYAN/venv/lib/python3.13/site-packages/django/template/backends/django.py", line 107, in render
    return self.template.render(context)
           ~~~~~~~~~~~~~~~~~~~~^^^^^^^^^
  File "/home/pryog/NAVODAYAN/venv/lib/python3.13/site-packages/django/template/base.py", line 171, in render
    return self._render(context)
           ~~~~~~~~~~~~^^^^^^^^^
  File "/home/pryog/NAVODAYAN/venv/lib/python3.13/site-packages/django/template/base.py", line 163, in _render
    return self.nodelist.render(context)
           ~~~~~~~~~~~~~~~~~~~~^^^^^^^^^
  File "/home/pryog/NAVODAYAN/venv/lib/python3.13/site-packages/django/template/base.py", line 1016, in render
    return SafeString("".join([node.render_annotated(context) for node in self]))
                               ~~~~~~~~~~~~~~~~~~~~~^^^^^^^^^
  File "/home/pryog/NAVODAYAN/venv/lib/python3.13/site-packages/django/template/base.py", line 977, in render_annotated
    return self.render(context)
           ~~~~~~~~~~~^^^^^^^^^
  File "/home/pryog/NAVODAYAN/venv/lib/python3.13/site-packages/django/template/defaulttags.py", line 480, in render
    url = reverse(view_name, args=args, kwargs=kwargs, current_app=current_app)
  File "/home/pryog/NAVODAYAN/venv/lib/python3.13/site-packages/django/urls/base.py", line 98, in reverse
    resolved_url = resolver._reverse_with_prefix(view, prefix, *args, **kwargs)
  File "/home/pryog/NAVODAYAN/venv/lib/python3.13/site-packages/django/urls/resolvers.py", line 831, in _reverse_with_prefix
    raise NoReverseMatch(msg)
django.urls.exceptions.NoReverseMatch: Reverse for 'download' not found. 'download' is not a valid view function or pattern name.
Internal Server Error: /
Traceback (most recent call last):
  File "/home/pryog/NAVODAYAN/venv/lib/python3.13/site-packages/asgiref/sync.py", line 518, in thread_handler
    raise exc_info[1]
  File "/home/pryog/NAVODAYAN/venv/lib/python3.13/site-packages/django/core/handlers/exception.py", line 42, in inner
    response = await get_response(request)
               ^^^^^^^^^^^^^^^^^^^^^^^^^^^
  File "/home/pryog/NAVODAYAN/venv/lib/python3.13/site-packages/asgiref/sync.py", line 518, in thread_handler
    raise exc_info[1]
  File "/home/pryog/NAVODAYAN/venv/lib/python3.13/site-packages/django/core/handlers/base.py", line 253, in _get_response_async
    response = await wrapped_callback(
               ^^^^^^^^^^^^^^^^^^^^^^^
        request, *callback_args, **callback_kwargs
        ^^^^^^^^^^^^^^^^^^^^^^^^^^^^^^^^^^^^^^^^^^
    )
    ^
  File "/home/pryog/NAVODAYAN/venv/lib/python3.13/site-packages/asgiref/sync.py", line 468, in __call__
    ret = await asyncio.shield(exec_coro)
          ^^^^^^^^^^^^^^^^^^^^^^^^^^^^^^^
  File "/home/pryog/NAVODAYAN/venv/lib/python3.13/site-packages/asgiref/current_thread_executor.py", line 40, in run
    result = self.fn(*self.args, **self.kwargs)
  File "/home/pryog/NAVODAYAN/venv/lib/python3.13/site-packages/asgiref/sync.py", line 522, in thread_handler
    return func(*args, **kwargs)
  File "/home/pryog/NAVODAYAN/haminavodayaho/website/views.py", line 16, in index
    return render(request, 'website/index.html', context)
  File "/home/pryog/NAVODAYAN/venv/lib/python3.13/site-packages/django/shortcuts.py", line 25, in render
    content = loader.render_to_string(template_name, context, request, using=using)
  File "/home/pryog/NAVODAYAN/venv/lib/python3.13/site-packages/django/template/loader.py", line 62, in render_to_string
    return template.render(context, request)
           ~~~~~~~~~~~~~~~^^^^^^^^^^^^^^^^^^
  File "/home/pryog/NAVODAYAN/venv/lib/python3.13/site-packages/django/template/backends/django.py", line 107, in render
    return self.template.render(context)
           ~~~~~~~~~~~~~~~~~~~~^^^^^^^^^
  File "/home/pryog/NAVODAYAN/venv/lib/python3.13/site-packages/django/template/base.py", line 171, in render
    return self._render(context)
           ~~~~~~~~~~~~^^^^^^^^^
  File "/home/pryog/NAVODAYAN/venv/lib/python3.13/site-packages/django/template/base.py", line 163, in _render
    return self.nodelist.render(context)
           ~~~~~~~~~~~~~~~~~~~~^^^^^^^^^
  File "/home/pryog/NAVODAYAN/venv/lib/python3.13/site-packages/django/template/base.py", line 1016, in render
    return SafeString("".join([node.render_annotated(context) for node in self]))
                               ~~~~~~~~~~~~~~~~~~~~~^^^^^^^^^
  File "/home/pryog/NAVODAYAN/venv/lib/python3.13/site-packages/django/template/base.py", line 977, in render_annotated
    return self.render(context)
           ~~~~~~~~~~~^^^^^^^^^
  File "/home/pryog/NAVODAYAN/venv/lib/python3.13/site-packages/django/template/defaulttags.py", line 480, in render
    url = reverse(view_name, args=args, kwargs=kwargs, current_app=current_app)
  File "/home/pryog/NAVODAYAN/venv/lib/python3.13/site-packages/django/urls/base.py", line 98, in reverse
    resolved_url = resolver._reverse_with_prefix(view, prefix, *args, **kwargs)
  File "/home/pryog/NAVODAYAN/venv/lib/python3.13/site-packages/django/urls/resolvers.py", line 831, in _reverse_with_prefix
    raise NoReverseMatch(msg)
django.urls.exceptions.NoReverseMatch: Reverse for 'download' not found. 'download' is not a valid view function or pattern name.
Internal Server Error: /
Traceback (most recent call last):
  File "/home/pryog/NAVODAYAN/venv/lib/python3.13/site-packages/django/db/backends/utils.py", line 105, in _execute
    return self.cursor.execute(sql, params)
           ~~~~~~~~~~~~~~~~~~~^^^^^^^^^^^^^
  File "/home/pryog/NAVODAYAN/venv/lib/python3.13/site-packages/psycopg/cursor.py", line 97, in execute
    raise ex.with_traceback(None)
psycopg.errors.UndefinedTable: relation "website_aboutsection" does not exist
LINE 1: ...on"."image", "website_aboutsection"."image2" FROM "website_a...
                                                             ^

The above exception was the direct cause of the following exception:

Traceback (most recent call last):
  File "/home/pryog/NAVODAYAN/venv/lib/python3.13/site-packages/asgiref/sync.py", line 518, in thread_handler
    raise exc_info[1]
  File "/home/pryog/NAVODAYAN/venv/lib/python3.13/site-packages/django/core/handlers/exception.py", line 42, in inner
    response = await get_response(request)
               ^^^^^^^^^^^^^^^^^^^^^^^^^^^
  File "/home/pryog/NAVODAYAN/venv/lib/python3.13/site-packages/asgiref/sync.py", line 518, in thread_handler
    raise exc_info[1]
  File "/home/pryog/NAVODAYAN/venv/lib/python3.13/site-packages/django/core/handlers/base.py", line 253, in _get_response_async
    response = await wrapped_callback(
               ^^^^^^^^^^^^^^^^^^^^^^^
        request, *callback_args, **callback_kwargs
        ^^^^^^^^^^^^^^^^^^^^^^^^^^^^^^^^^^^^^^^^^^
    )
    ^
  File "/home/pryog/NAVODAYAN/venv/lib/python3.13/site-packages/asgiref/sync.py", line 468, in __call__
    ret = await asyncio.shield(exec_coro)
          ^^^^^^^^^^^^^^^^^^^^^^^^^^^^^^^
  File "/home/pryog/NAVODAYAN/venv/lib/python3.13/site-packages/asgiref/current_thread_executor.py", line 40, in run
    result = self.fn(*self.args, **self.kwargs)
  File "/home/pryog/NAVODAYAN/venv/lib/python3.13/site-packages/asgiref/sync.py", line 522, in thread_handler
    return func(*args, **kwargs)
  File "/home/pryog/NAVODAYAN/haminavodayaho/website/views.py", line 13, in index
    "about": AboutSection.objects.first(),
             ~~~~~~~~~~~~~~~~~~~~~~~~~~^^
  File "/home/pryog/NAVODAYAN/venv/lib/python3.13/site-packages/django/db/models/manager.py", line 87, in manager_method
    return getattr(self.get_queryset(), name)(*args, **kwargs)
           ~~~~~~~~~~~~~~~~~~~~~~~~~~~~~~~~~~^^^^^^^^^^^^^^^^^
  File "/home/pryog/NAVODAYAN/venv/lib/python3.13/site-packages/django/db/models/query.py", line 1104, in first
    for obj in queryset[:1]:
               ~~~~~~~~^^^^
  File "/home/pryog/NAVODAYAN/venv/lib/python3.13/site-packages/django/db/models/query.py", line 384, in __iter__
    self._fetch_all()
    ~~~~~~~~~~~~~~~^^
  File "/home/pryog/NAVODAYAN/venv/lib/python3.13/site-packages/django/db/models/query.py", line 1935, in _fetch_all
    self._result_cache = list(self._iterable_class(self))
                         ~~~~^^^^^^^^^^^^^^^^^^^^^^^^^^^^
  File "/home/pryog/NAVODAYAN/venv/lib/python3.13/site-packages/django/db/models/query.py", line 91, in __iter__
    results = compiler.execute_sql(
        chunked_fetch=self.chunked_fetch, chunk_size=self.chunk_size
    )
  File "/home/pryog/NAVODAYAN/venv/lib/python3.13/site-packages/django/db/models/sql/compiler.py", line 1622, in execute_sql
    cursor.execute(sql, params)
    ~~~~~~~~~~~~~~^^^^^^^^^^^^^
  File "/home/pryog/NAVODAYAN/venv/lib/python3.13/site-packages/django/db/backends/utils.py", line 79, in execute
    return self._execute_with_wrappers(
           ~~~~~~~~~~~~~~~~~~~~~~~~~~~^
        sql, params, many=False, executor=self._execute
        ^^^^^^^^^^^^^^^^^^^^^^^^^^^^^^^^^^^^^^^^^^^^^^^
    )
    ^
  File "/home/pryog/NAVODAYAN/venv/lib/python3.13/site-packages/django/db/backends/utils.py", line 92, in _execute_with_wrappers
    return executor(sql, params, many, context)
  File "/home/pryog/NAVODAYAN/venv/lib/python3.13/site-packages/django/db/backends/utils.py", line 100, in _execute
    with self.db.wrap_database_errors:
         ^^^^^^^^^^^^^^^^^^^^^^^^^^^^
  File "/home/pryog/NAVODAYAN/venv/lib/python3.13/site-packages/django/db/utils.py", line 91, in __exit__
    raise dj_exc_value.with_traceback(traceback) from exc_value
  File "/home/pryog/NAVODAYAN/venv/lib/python3.13/site-packages/django/db/backends/utils.py", line 105, in _execute
    return self.cursor.execute(sql, params)
           ~~~~~~~~~~~~~~~~~~~^^^^^^^^^^^^^
  File "/home/pryog/NAVODAYAN/venv/lib/python3.13/site-packages/psycopg/cursor.py", line 97, in execute
    raise ex.with_traceback(None)
django.db.utils.ProgrammingError: relation "website_aboutsection" does not exist
LINE 1: ...on"."image", "website_aboutsection"."image2" FROM "website_a...
                                                             ^
Internal Server Error: /
Traceback (most recent call last):
  File "/home/pryog/NAVODAYAN/venv/lib/python3.13/site-packages/django/db/backends/utils.py", line 105, in _execute
    return self.cursor.execute(sql, params)
           ~~~~~~~~~~~~~~~~~~~^^^^^^^^^^^^^
  File "/home/pryog/NAVODAYAN/venv/lib/python3.13/site-packages/psycopg/cursor.py", line 97, in execute
    raise ex.with_traceback(None)
psycopg.errors.UndefinedTable: relation "website_aboutsection" does not exist
LINE 1: ...on"."image", "website_aboutsection"."image2" FROM "website_a...
                                                             ^

The above exception was the direct cause of the following exception:

Traceback (most recent call last):
  File "/home/pryog/NAVODAYAN/venv/lib/python3.13/site-packages/asgiref/sync.py", line 518, in thread_handler
    raise exc_info[1]
  File "/home/pryog/NAVODAYAN/venv/lib/python3.13/site-packages/django/core/handlers/exception.py", line 42, in inner
    response = await get_response(request)
               ^^^^^^^^^^^^^^^^^^^^^^^^^^^
  File "/home/pryog/NAVODAYAN/venv/lib/python3.13/site-packages/asgiref/sync.py", line 518, in thread_handler
    raise exc_info[1]
  File "/home/pryog/NAVODAYAN/venv/lib/python3.13/site-packages/django/core/handlers/base.py", line 253, in _get_response_async
    response = await wrapped_callback(
               ^^^^^^^^^^^^^^^^^^^^^^^
        request, *callback_args, **callback_kwargs
        ^^^^^^^^^^^^^^^^^^^^^^^^^^^^^^^^^^^^^^^^^^
    )
    ^
  File "/home/pryog/NAVODAYAN/venv/lib/python3.13/site-packages/asgiref/sync.py", line 468, in __call__
    ret = await asyncio.shield(exec_coro)
          ^^^^^^^^^^^^^^^^^^^^^^^^^^^^^^^
  File "/home/pryog/NAVODAYAN/venv/lib/python3.13/site-packages/asgiref/current_thread_executor.py", line 40, in run
    result = self.fn(*self.args, **self.kwargs)
  File "/home/pryog/NAVODAYAN/venv/lib/python3.13/site-packages/asgiref/sync.py", line 522, in thread_handler
    return func(*args, **kwargs)
  File "/home/pryog/NAVODAYAN/haminavodayaho/website/views.py", line 13, in index
    "about": AboutSection.objects.first(),
             ~~~~~~~~~~~~~~~~~~~~~~~~~~^^
  File "/home/pryog/NAVODAYAN/venv/lib/python3.13/site-packages/django/db/models/manager.py", line 87, in manager_method
    return getattr(self.get_queryset(), name)(*args, **kwargs)
           ~~~~~~~~~~~~~~~~~~~~~~~~~~~~~~~~~~^^^^^^^^^^^^^^^^^
  File "/home/pryog/NAVODAYAN/venv/lib/python3.13/site-packages/django/db/models/query.py", line 1104, in first
    for obj in queryset[:1]:
               ~~~~~~~~^^^^
  File "/home/pryog/NAVODAYAN/venv/lib/python3.13/site-packages/django/db/models/query.py", line 384, in __iter__
    self._fetch_all()
    ~~~~~~~~~~~~~~~^^
  File "/home/pryog/NAVODAYAN/venv/lib/python3.13/site-packages/django/db/models/query.py", line 1935, in _fetch_all
    self._result_cache = list(self._iterable_class(self))
                         ~~~~^^^^^^^^^^^^^^^^^^^^^^^^^^^^
  File "/home/pryog/NAVODAYAN/venv/lib/python3.13/site-packages/django/db/models/query.py", line 91, in __iter__
    results = compiler.execute_sql(
        chunked_fetch=self.chunked_fetch, chunk_size=self.chunk_size
    )
  File "/home/pryog/NAVODAYAN/venv/lib/python3.13/site-packages/django/db/models/sql/compiler.py", line 1622, in execute_sql
    cursor.execute(sql, params)
    ~~~~~~~~~~~~~~^^^^^^^^^^^^^
  File "/home/pryog/NAVODAYAN/venv/lib/python3.13/site-packages/django/db/backends/utils.py", line 122, in execute
    return super().execute(sql, params)
           ~~~~~~~~~~~~~~~^^^^^^^^^^^^^
  File "/home/pryog/NAVODAYAN/venv/lib/python3.13/site-packages/django/db/backends/utils.py", line 79, in execute
    return self._execute_with_wrappers(
           ~~~~~~~~~~~~~~~~~~~~~~~~~~~^
        sql, params, many=False, executor=self._execute
        ^^^^^^^^^^^^^^^^^^^^^^^^^^^^^^^^^^^^^^^^^^^^^^^
    )
    ^
  File "/home/pryog/NAVODAYAN/venv/lib/python3.13/site-packages/django/db/backends/utils.py", line 92, in _execute_with_wrappers
    return executor(sql, params, many, context)
  File "/home/pryog/NAVODAYAN/venv/lib/python3.13/site-packages/django/db/backends/utils.py", line 100, in _execute
    with self.db.wrap_database_errors:
         ^^^^^^^^^^^^^^^^^^^^^^^^^^^^
  File "/home/pryog/NAVODAYAN/venv/lib/python3.13/site-packages/django/db/utils.py", line 91, in __exit__
    raise dj_exc_value.with_traceback(traceback) from exc_value
  File "/home/pryog/NAVODAYAN/venv/lib/python3.13/site-packages/django/db/backends/utils.py", line 105, in _execute
    return self.cursor.execute(sql, params)
           ~~~~~~~~~~~~~~~~~~~^^^^^^^^^^^^^
  File "/home/pryog/NAVODAYAN/venv/lib/python3.13/site-packages/psycopg/cursor.py", line 97, in execute
    raise ex.with_traceback(None)
django.db.utils.ProgrammingError: relation "website_aboutsection" does not exist
LINE 1: ...on"."image", "website_aboutsection"."image2" FROM "website_a...
                                                             ^
